Workbook

Sheet dashboard
A1: 次の番号 / 登録ダッシュボード（自動計算）
A3: line_id | B3: colony数 | C3: 最大番号 | D3: 次のbirth_id | E3: 若♂(週) | F3: 若♀(週)
A4: =lines!A2 -> wt | B4: =COUNTIF(colony!$B:$B,A4) -> 192 | C4: =SUMPRODUCT(MAX((colony!$B$2:$B$3000=A4)*colony!$C$2:$C$3000)) -> 192 | D4: =IF(A4="","",A4&"-"&(C4+1)) -> wt-193 | E4: =IF(SUMPRODUCT(MAX((colony!$B$2:$B$3000=A4)*(colony!$D$2:$D$3000="M")*(colony!$R$2:$R$3000<>"sacrificed")*(colony!$R$2:$R$3000<>"dead")*(colony!$R$2:$R$3000<>"transferred")*(colony!$R$2:$R$3000<>"missing")*colony!$E$2:$E$3000))=0,"-",ROUND((TODAY()-SUMPRODUCT(MAX((colony!$B$2:$B$3000=A4)*(colony!$D$2:$D$3000="M")*(colony!$R$2:$R$3000<>"sacrificed")*(colony!$R$2:$R$3000<>"dead")*(colony!$R$2:$R$3000<>"transferred")*(colony!$R$2:$R$3000<>"missing")*colony!$E$2:$E$3000)))/7,1)) -> 8.6 | F4: =IF(SUMPRODUCT(MAX((colony!$B$2:$B$3000=A4)*(colony!$D$2:$D$3000="F")*(colony!$R$2:$R$3000<>"sacrificed")*(colony!$R$2:$R$3000<>"dead")*(colony!$R$2:$R$3000<>"transferred")*(colony!$R$2:$R$3000<>"missing")*colony!$E$2:$E$3000))=0,"-",ROUND((TODAY()-SUMPRODUCT(MAX((colony!$B$2:$B$3000=A4)*(colony!$D$2:$D$3000="F")*(colony!$R$2:$R$3000<>"sacrificed")*(colony!$R$2:$R$3000<>"dead")*(colony!$R$2:$R$3000<>"transferred")*(colony!$R$2:$R$3000<>"missing")*colony!$E$2:$E$3000)))/7,1)) -> 15.6
A5: =lines!A3 -> aqp4ko | B5: =COUNTIF(colony!$B:$B,A5) -> 121 | C5: =SUMPRODUCT(MAX((colony!$B$2:$B$3000=A5)*colony!$C$2:$C$3000)) -> 121 | D5: =IF(A5="","",A5&"-"&(C5+1)) -> aqp4ko-122 | E5: =IF(SUMPRODUCT(MAX((colony!$B$2:$B$3000=A5)*(colony!$D$2:$D$3000="M")*(colony!$R$2:$R$3000<>"sacrificed")*(colony!$R$2:$R$3000<>"dead")*(colony!$R$2:$R$3000<>"transferred")*(colony!$R$2:$R$3000<>"missing")*colony!$E$2:$E$3000))=0,"-",ROUND((TODAY()-SUMPRODUCT(MAX((colony!$B$2:$B$3000=A5)*(colony!$D$2:$D$3000="M")*(colony!$R$2:$R$3000<>"sacrificed")*(colony!$R$2:$R$3000<>"dead")*(colony!$R$2:$R$3000<>"transferred")*(colony!$R$2:$R$3000<>"missing")*colony!$E$2:$E$3000)))/7,1)) -> 19 | F5: =IF(SUMPRODUCT(MAX((colony!$B$2:$B$3000=A5)*(colony!$D$2:$D$3000="F")*(colony!$R$2:$R$3000<>"sacrificed")*(colony!$R$2:$R$3000<>"dead")*(colony!$R$2:$R$3000<>"transferred")*(colony!$R$2:$R$3000<>"missing")*colony!$E$2:$E$3000))=0,"-",ROUND((TODAY()-SUMPRODUCT(MAX((colony!$B$2:$B$3000=A5)*(colony!$D$2:$D$3000="F")*(colony!$R$2:$R$3000<>"sacrificed")*(colony!$R$2:$R$3000<>"dead")*(colony!$R$2:$R$3000<>"transferred")*(colony!$R$2:$R$3000<>"missing")*colony!$E$2:$E$3000)))/7,1)) -> 19
A6: =lines!A4 -> cagegfp | B6: =COUNTIF(colony!$B:$B,A6) -> 150 | C6: =SUMPRODUCT(MAX((colony!$B$2:$B$3000=A6)*colony!$C$2:$C$3000)) -> 150 | D6: =IF(A6="","",A6&"-"&(C6+1)) -> cagegfp-151 | E6: =IF(SUMPRODUCT(MAX((colony!$B$2:$B$3000=A6)*(colony!$D$2:$D$3000="M")*(colony!$R$2:$R$3000<>"sacrificed")*(colony!$R$2:$R$3000<>"dead")*(colony!$R$2:$R$3000<>"transferred")*(colony!$R$2:$R$3000<>"missing")*colony!$E$2:$E$3000))=0,"-",ROUND((TODAY()-SUMPRODUCT(MAX((colony!$B$2:$B$3000=A6)*(colony!$D$2:$D$3000="M")*(colony!$R$2:$R$3000<>"sacrificed")*(colony!$R$2:$R$3000<>"dead")*(colony!$R$2:$R$3000<>"transferred")*(colony!$R$2:$R$3000<>"missing")*colony!$E$2:$E$3000)))/7,1)) -> 17.1 | F6: =IF(SUMPRODUCT(MAX((colony!$B$2:$B$3000=A6)*(colony!$D$2:$D$3000="F")*(colony!$R$2:$R$3000<>"sacrificed")*(colony!$R$2:$R$3000<>"dead")*(colony!$R$2:$R$3000<>"transferred")*(colony!$R$2:$R$3000<>"missing")*colony!$E$2:$E$3000))=0,"-",ROUND((TODAY()-SUMPRODUCT(MAX((colony!$B$2:$B$3000=A6)*(colony!$D$2:$D$3000="F")*(colony!$R$2:$R$3000<>"sacrificed")*(colony!$R$2:$R$3000<>"dead")*(colony!$R$2:$R$3000<>"transferred")*(colony!$R$2:$R$3000<>"missing")*colony!$E$2:$E$3000)))/7,1)) -> 25.4
A7: =lines!A5 -> cagegfp_aqp4ko | B7: =COUNTIF(colony!$B:$B,A7) -> 121 | C7: =SUMPRODUCT(MAX((colony!$B$2:$B$3000=A7)*colony!$C$2:$C$3000)) -> 121 | D7: =IF(A7="","",A7&"-"&(C7+1)) -> cagegfp_aqp4ko-122 | E7: =IF(SUMPRODUCT(MAX((colony!$B$2:$B$3000=A7)*(colony!$D$2:$D$3000="M")*(colony!$R$2:$R$3000<>"sacrificed")*(colony!$R$2:$R$3000<>"dead")*(colony!$R$2:$R$3000<>"transferred")*(colony!$R$2:$R$3000<>"missing")*colony!$E$2:$E$3000))=0,"-",ROUND((TODAY()-SUMPRODUCT(MAX((colony!$B$2:$B$3000=A7)*(colony!$D$2:$D$3000="M")*(colony!$R$2:$R$3000<>"sacrificed")*(colony!$R$2:$R$3000<>"dead")*(colony!$R$2:$R$3000<>"transferred")*(colony!$R$2:$R$3000<>"missing")*colony!$E$2:$E$3000)))/7,1)) -> 13.7 | F7: =IF(SUMPRODUCT(MAX((colony!$B$2:$B$3000=A7)*(colony!$D$2:$D$3000="F")*(colony!$R$2:$R$3000<>"sacrificed")*(colony!$R$2:$R$3000<>"dead")*(colony!$R$2:$R$3000<>"transferred")*(colony!$R$2:$R$3000<>"missing")*colony!$E$2:$E$3000))=0,"-",ROUND((TODAY()-SUMPRODUCT(MAX((colony!$B$2:$B$3000=A7)*(colony!$D$2:$D$3000="F")*(colony!$R$2:$R$3000<>"sacrificed")*(colony!$R$2:$R$3000<>"dead")*(colony!$R$2:$R$3000<>"transferred")*(colony!$R$2:$R$3000<>"missing")*colony!$E$2:$E$3000)))/7,1)) -> 13.7
A8: =lines!A6 -> 5xfad | B8: =COUNTIF(colony!$B:$B,A8) -> 138 | C8: =SUMPRODUCT(MAX((colony!$B$2:$B$3000=A8)*colony!$C$2:$C$3000)) -> 138 | D8: =IF(A8="","",A8&"-"&(C8+1)) -> 5xfad-139 | E8: =IF(SUMPRODUCT(MAX((colony!$B$2:$B$3000=A8)*(colony!$D$2:$D$3000="M")*(colony!$R$2:$R$3000<>"sacrificed")*(colony!$R$2:$R$3000<>"dead")*(colony!$R$2:$R$3000<>"transferred")*(colony!$R$2:$R$3000<>"missing")*colony!$E$2:$E$3000))=0,"-",ROUND((TODAY()-SUMPRODUCT(MAX((colony!$B$2:$B$3000=A8)*(colony!$D$2:$D$3000="M")*(colony!$R$2:$R$3000<>"sacrificed")*(colony!$R$2:$R$3000<>"dead")*(colony!$R$2:$R$3000<>"transferred")*(colony!$R$2:$R$3000<>"missing")*colony!$E$2:$E$3000)))/7,1)) -> 34.1 | F8: =IF(SUMPRODUCT(MAX((colony!$B$2:$B$3000=A8)*(colony!$D$2:$D$3000="F")*(colony!$R$2:$R$3000<>"sacrificed")*(colony!$R$2:$R$3000<>"dead")*(colony!$R$2:$R$3000<>"transferred")*(colony!$R$2:$R$3000<>"missing")*colony!$E$2:$E$3000))=0,"-",ROUND((TODAY()-SUMPRODUCT(MAX((colony!$B$2:$B$3000=A8)*(colony!$D$2:$D$3000="F")*(colony!$R$2:$R$3000<>"sacrificed")*(colony!$R$2:$R$3000<>"dead")*(colony!$R$2:$R$3000<>"transferred")*(colony!$R$2:$R$3000<>"missing")*colony!$E$2:$E$3000)))/7,1)) -> 34.1
A9: =lines!A7 -> 5xfad_aqp4ko | B9: =COUNTIF(colony!$B:$B,A9) -> 99 | C9: =SUMPRODUCT(MAX((colony!$B$2:$B$3000=A9)*colony!$C$2:$C$3000)) -> 99 | D9: =IF(A9="","",A9&"-"&(C9+1)) -> 5xfad_aqp4ko-100 | E9: =IF(SUMPRODUCT(MAX((colony!$B$2:$B$3000=A9)*(colony!$D$2:$D$3000="M")*(colony!$R$2:$R$3000<>"sacrificed")*(colony!$R$2:$R$3000<>"dead")*(colony!$R$2:$R$3000<>"transferred")*(colony!$R$2:$R$3000<>"missing")*colony!$E$2:$E$3000))=0,"-",ROUND((TODAY()-SUMPRODUCT(MAX((colony!$B$2:$B$3000=A9)*(colony!$D$2:$D$3000="M")*(colony!$R$2:$R$3000<>"sacrificed")*(colony!$R$2:$R$3000<>"dead")*(colony!$R$2:$R$3000<>"transferred")*(colony!$R$2:$R$3000<>"missing")*colony!$E$2:$E$3000)))/7,1)) -> 34 | F9: =IF(SUMPRODUCT(MAX((colony!$B$2:$B$3000=A9)*(colony!$D$2:$D$3000="F")*(colony!$R$2:$R$3000<>"sacrificed")*(colony!$R$2:$R$3000<>"dead")*(colony!$R$2:$R$3000<>"transferred")*(colony!$R$2:$R$3000<>"missing")*colony!$E$2:$E$3000))=0,"-",ROUND((TODAY()-SUMPRODUCT(MAX((colony!$B$2:$B$3000=A9)*(colony!$D$2:$D$3000="F")*(colony!$R$2:$R$3000<>"sacrificed")*(colony!$R$2:$R$3000<>"dead")*(colony!$R$2:$R$3000<>"transferred")*(colony!$R$2:$R$3000<>"missing")*colony!$E$2:$E$3000)))/7,1)) -> 34
A11: 担当 | B11: animals数 | C11: 最大連番 | D11: 次のmouse_id
A12: ts | B12: =SUMPRODUCT((LEFT(animals!$A$2:$A$600,2)=A12)*1) -> 300 | C12: =SUMPRODUCT(MAX((LEFT(animals!$A$2:$A$600,2)=A12)*IFERROR(VALUE(MID(animals!$A$2:$A$600,3,9)),0))) -> 300 | D12: =A12&(C12+1) -> ts301
A13: sk | B13: =SUMPRODUCT((LEFT(animals!$A$2:$A$600,2)=A13)*1) -> 100 | C13: =SUMPRODUCT(MAX((LEFT(animals!$A$2:$A$600,2)=A13)*IFERROR(VALUE(MID(animals!$A$2:$A$600,3,9)),0))) -> 100 | D13: =A13&(C13+1) -> sk101
A16: colony総数 | B16: =COUNTA(colony!$A$2:$A$3000) -> 821
A17: alive | B17: =COUNTIF(colony!$R:$R,"alive") -> 159
A18: genotyping pending | B18: =COUNTIF(colony!$Q:$Q,"pending") -> 67
A19: enrolled animals | B19: =COUNTA(animals!$A$2:$A$600) -> 400
A20: enrollment 行数 | B20: =COUNTA(enrollments!$A$2:$A$500) -> 0

Sheet vocab
A1: sex | B1: genotype_status | C1: genotype_call | D1: animal_status | E1: exp_status | F1: role | G1: source | H1: mating_status | I1: cohort | J1: procedure_type | K1: route | L1: anesthesia | M1: hemisphere | N1: fixation | O1: operator
A2: M | B2: pending | C2: +/+ | D2: alive | E2: planned | F2: experimental | G2: in_house | H2: paired | I2: personal | J2: cranial_window | K2: iv | L2: isoflurane | M2: R | N2: none | O2: ts
A3: F | B3: confirmed | C3: +/- | D3: breeding | E3: active | F3: control | G3: vendor | H3: littered | I3: collab | J3: PoRTs_window | K3: icm | L3: ketamine_xylazine | M3: L | N3: PFA_perfusion | O3: sk
A4: U | B4: failed | C4: -/- | D4: nursing | E4: completed | F4: littermate_control | H4: weaned | J4: craniotomy | K4: intracortical | L4: avertin | M4: midline | N4: immersion
B5: retest | C5: + | D5: mating | E5: excluded | F5: naive | H5: ended | J5: viral_injection | K5: ip | L5: urethane | N5: other
B6: na | C6: - | D6: mating_planned | J6: CM_injection | K6: sc | L6: other
C7: na | D7: weaned | J7: ICM_injection | K7: none
D8: sacrificed | J8: CSF_collection
D9: dead | J9: femoral_catheter
D10: transferred | J10: perfusion_fix
D11: missing | J11: tissue_clearing
J12: brain_sampling
J13: imaging
J14: genotyping_biopsy
J15: other

Sheet lines
A1: line_id | B1: line_name | C1: genotype_expected | D1: background | E1: source | F1: assays | G1: notes
A2: wt | B2: wild-type B6 | C2: +/+ | D2: C57BL/6JJcl | E2: vendor | G2: CLEA
A3: aqp4ko | B3: Aqp4 KO | C3: Aqp4 -/- | D3: C57BL/6J | E3: in_house | F3: aqp4 | G3: KO
A4: cagegfp | B4: CAG-EGFP Tg | C4: Tg(CAG-EGFP) | D4: C57BL/6 | E4: vendor | F4: cagegfp | G4: RIKEN
A5: cagegfp_aqp4ko | B5: CAG-EGFP x Aqp4KO | C5: CAG-EGFP;Aqp4-/- | D5: C57BL/6 | E5: in_house | F5: cagegfp,aqp4 | G5: cross
A6: 5xfad | B6: 5xFAD Tg | C6: 5xFAD hemi | D6: C57BL/6 | E6: vendor | F6: app,ps1 | G6: Jackson
A7: 5xfad_aqp4ko | B7: 5xFAD x Aqp4KO | C7: 5xFAD;Aqp4-/- | D7: C57BL/6 | E7: in_house | F7: app,ps1,aqp4 | G7: cross

Sheet colony
A1: birth_id | B1: line_id | C1: number | D1: sex | E1: dob | F1: age_weeks | G1: source | H1: litter_id | I1: sire | J1: dam | K1: generation | L1: gt_app | M1: gt_ps1 | N1: gt_aqp4 | O1: gt_cagegfp | P1: genotype | Q1: genotype_status | R1: status | S1: status_date | T1: notes
A2: 5xfad-112 | B2: 5xfad | C2: 112 | D2: M | E2: 45832 | F2: =IF(E2="","",ROUND((TODAY()-E2)/7,1)) -> 50.7 | G2: in_house | I2: 108or109or110 | J2: 5xFAD-95(WT) | K2: 5 | L2: -/- | M2: -/- | P2: =MID(IF(L2="","","; APP:"&L2)&IF(M2="","","; PS1:"&M2)&IF(N2="","","; AQP4:"&N2)&IF(O2="","","; CAG-EGFP:"&O2),3,200) -> APP:-/-; PS1:-/- | Q2: confirmed | R2: alive | T2: tag:Punch
A3: 5xfad-113 | B3: 5xfad | C3: 113 | D3: M | E3: 45832 | F3: =IF(E3="","",ROUND((TODAY()-E3)/7,1)) -> 50.7 | G3: in_house | I3: 108or109or110 | J3: 5xFAD-95(WT) | K3: 5 | L3: +/- | M3: +/- | P3: =MID(IF(L3="","","; APP:"&L3)&IF(M3="","","; PS1:"&M3)&IF(N3="","","; AQP4:"&N3)&IF(O3="","","; CAG-EGFP:"&O3),3,200) -> APP:+/-; PS1:+/- | Q3: confirmed | R3: alive | T3: tag:Punch
A4: 5xfad-114 | B4: 5xfad | C4: 114 | D4: F | E4: 45832 | F4: =IF(E4="","",ROUND((TODAY()-E4)/7,1)) -> 50.7 | G4: in_house | I4: 108or109or110 | J4: 5xFAD-95(WT) | K4: 5 | L4: +/- | M4: +/- | P4: =MID(IF(L4="","","; APP:"&L4)&IF(M4="","","; PS1:"&M4)&IF(N4="","","; AQP4:"&N4)&IF(O4="","","; CAG-EGFP:"&O4),3,200) -> APP:+/-; PS1:+/- | Q4: confirmed | R4: alive | T4: →Nuriya G tag:Punch orig:実験中
A5: 5xfad-115 | B5: 5xfad | C5: 115 | D5: F | E5: 45832 | F5: =IF(E5="","",ROUND((TODAY()-E5)/7,1)) -> 50.7 | G5: in_house | I5: 108or109or110 | J5: 5xFAD-95(WT) | K5: 5 | L5: -/- | M5: -/- | P5: =MID(IF(L5="","","; APP:"&L5)&IF(M5="","","; PS1:"&M5)&IF(N5="","","; AQP4:"&N5)&IF(O5="","","; CAG-EGFP:"&O5),3,200) -> APP:-/-; PS1:-/- | Q5: confirmed | R5: alive | T5: →Nuriya G tag:Punch
A6: 5xfad-116 | B6: 5xfad | C6: 116 | D6: F | E6: 45832 | F6: =IF(E6="","",ROUND((TODAY()-E6)/7,1)) -> 50.7 | G6: in_house | I6: 108or109or110 | J6: 5xFAD-95(WT) | K6: 5 | L6: -/- | M6: -/- | P6: =MID(IF(L6="","","; APP:"&L6)&IF(M6="","","; PS1:"&M6)&IF(N6="","","; AQP4:"&N6)&IF(O6="","","; CAG-EGFP:"&O6),3,200) -> APP:-/-; PS1:-/- | Q6: confirmed | R6: alive | T6: tag:Punch orig:実験中
A7: 5xfad-117 | B7: 5xfad | C7: 117 | D7: F | E7: 45832 | F7: =IF(E7="","",ROUND((TODAY()-E7)/7,1)) -> 50.7 | G7: in_house | I7: 108or109or110 | J7: 5xFAD-95(WT) | K7: 5 | L7: +/- | M7: +/- | P7: =MID(IF(L7="","","; APP:"&L7)&IF(M7="","","; PS1:"&M7)&IF(N7="","","; AQP4:"&N7)&IF(O7="","","; CAG-EGFP:"&O7),3,200) -> APP:+/-; PS1:+/- | Q7: confirmed | R7: alive | T7: tag:Punch
A8: 5xfad-118 | B8: 5xfad | C8: 118 | D8: F | E8: 45832 | F8: =IF(E8="","",ROUND((TODAY()-E8)/7,1)) -> 50.7 | G8: in_house | I8: 108or109or110 | J8: 5xFAD-95(WT) | K8: 5 | L8: +/- | M8: +/- | P8: =MID(IF(L8="","","; APP:"&L8)&IF(M8="","","; PS1:"&M8)&IF(N8="","","; AQP4:"&N8)&IF(O8="","","; CAG-EGFP:"&O8),3,200) -> APP:+/-; PS1:+/- | Q8: confirmed | R8: alive | T8: tag:Punch
A9: 5xfad-119 | B9: 5xfad | C9: 119 | D9: F | E9: 45832 | F9: =IF(E9="","",ROUND((TODAY()-E9)/7,1)) -> 50.7 | G9: in_house | I9: 108or109or110 | J9: 5xFAD-95(WT) | K9: 5 | L9: +/- | M9: +/- | P9: =MID(IF(L9="","","; APP:"&L9)&IF(M9="","","; PS1:"&M9)&IF(N9="","","; AQP4:"&N9)&IF(O9="","","; CAG-EGFP:"&O9),3,200) -> APP:+/-; PS1:+/- | Q9: confirmed | R9: alive | T9: tag:Punch
A10: 5xfad-120 | B10: 5xfad | C10: 120 | D10: M | E10: 45948 | F10: =IF(E10="","",ROUND((TODAY()-E10)/7,1)) -> 34.1 | G10: in_house | I10: 5xFAD 102 | J10: WT 130 | L10: +/- | M10: +/- | P10: =MID(IF(L10="","","; APP:"&L10)&IF(M10="","","; PS1:"&M10)&IF(N10="","","; AQP4:"&N10)&IF(O10="","","; CAG-EGFP:"&O10),3,200) -> APP:+/-; PS1:+/- | Q10: confirmed | R10: alive | T10: 5 x FAD x AQP4KO交配用→5xFAD交配→260528交配終了 tag:Punch
A11: 5xfad-121 | B11: 5xfad | C11: 121 | D11: M | E11: 45948 | F11: =IF(E11="","",ROUND((TODAY()-E11)/7,1)) -> 34.1 | G11: in_house | I11: 5xFAD 102 | J11: WT 130 | L11: +/- | M11: +/- | P11: =MID(IF(L11="","","; APP:"&L11)&IF(M11="","","; PS1:"&M11)&IF(N11="","","; AQP4:"&N11)&IF(O11="","","; CAG-EGFP:"&O11),3,200) -> APP:+/-; PS1:+/- | Q11: confirmed | R11: alive | T11: 5 x FAD x AQP4KO交配用→5xFAD交配→260601交配終了 tag:Punch
A12: 5xfad-122 | B12: 5xfad | C12: 122 | D12: M | E12: 45948 | F12: =IF(E12="","",ROUND((TODAY()-E12)/7,1)) -> 34.1 | G12: in_house | I12: 5xFAD 102 | J12: WT 130 | L12: -/- | M12: -/- | P12: =MID(IF(L12="","","; APP:"&L12)&IF(M12="","","; PS1:"&M12)&IF(N12="","","; AQP4:"&N12)&IF(O12="","","; CAG-EGFP:"&O12),3,200) -> APP:-/-; PS1:-/- | Q12: confirmed | R12: alive | T12: tag:Punch
A13: 5xfad-123 | B13: 5xfad | C13: 123 | D13: F | E13: 45948 | F13: =IF(E13="","",ROUND((TODAY()-E13)/7,1)) -> 34.1 | G13: in_house | I13: 5xFAD 102 | J13: WT 130 | L13: -/- | M13: -/- | P13: =MID(IF(L13="","","; APP:"&L13)&IF(M13="","","; PS1:"&M13)&IF(N13="","","; AQP4:"&N13)&IF(O13="","","; CAG-EGFP:"&O13),3,200) -> APP:-/-; PS1:-/- | Q13: confirmed | R13: alive | T13: tag:Punch
A14: 5xfad-124 | B14: 5xfad | C14: 124 | D14: F | E14: 45948 | F14: =IF(E14="","",ROUND((TODAY()-E14)/7,1)) -> 34.1 | G14: in_house | I14: 5xFAD 102 | J14: WT 130 | L14: +/- | M14: +/- | P14: =MID(IF(L14="","","; APP:"&L14)&IF(M14="","","; PS1:"&M14)&IF(N14="","","; AQP4:"&N14)&IF(O14="","","; CAG-EGFP:"&O14),3,200) -> APP:+/-; PS1:+/- | Q14: confirmed | R14: alive | T14: 右目開いてない、左目白内障 tag:Punch orig:実験中
A15: 5xfad-125 | B15: 5xfad | C15: 125 | D15: F | E15: 45948 | F15: =IF(E15="","",ROUND((TODAY()-E15)/7,1)) -> 34.1 | G15: in_house | I15: 5xFAD 102 | J15: WT 130 | L15: -/- | M15: -/- | P15: =MID(IF(L15="","","; APP:"&L15)&IF(M15="","","; PS1:"&M15)&IF(N15="","","; AQP4:"&N15)&IF(O15="","","; CAG-EGFP:"&O15),3,200) -> APP:-/-; PS1:-/- | Q15: confirmed | R15: alive | T15: tag:Punch orig:実験中
A16: 5xfad-126 | B16: 5xfad | C16: 126 | E16: 46175 | F16: =IF(E16="","",ROUND((TODAY()-E16)/7,1)) -> 1.7 | G16: in_house | I16: 5xFAD 120 | J16: WT 181 | P16: =MID(IF(L16="","","; APP:"&L16)&IF(M16="","","; PS1:"&M16)&IF(N16="","","; AQP4:"&N16)&IF(O16="","","; CAG-EGFP:"&O16),3,200) | Q16: pending | R16: alive
A17: 5xfad-127 | B17: 5xfad | C17: 127 | E17: 46175 | F17: =IF(E17="","",ROUND((TODAY()-E17)/7,1)) -> 1.7 | G17: in_house | I17: 5xFAD 120 | J17: WT 181 | P17: =MID(IF(L17="","","; APP:"&L17)&IF(M17="","","; PS1:"&M17)&IF(N17="","","; AQP4:"&N17)&IF(O17="","","; CAG-EGFP:"&O17),3,200) | Q17: pending | R17: alive
A18: 5xfad-128 | B18: 5xfad | C18: 128 | E18: 46175 | F18: =IF(E18="","",ROUND((TODAY()-E18)/7,1)) -> 1.7 | G18: in_house | I18: 5xFAD 120 | J18: WT 181 | P18: =MID(IF(L18="","","; APP:"&L18)&IF(M18="","","; PS1:"&M18)&IF(N18="","","; AQP4:"&N18)&IF(O18="","","; CAG-EGFP:"&O18),3,200) | Q18: pending | R18: alive
A19: 5xfad-129 | B19: 5xfad | C19: 129 | E19: 46175 | F19: =IF(E19="","",ROUND((TODAY()-E19)/7,1)) -> 1.7 | G19: in_house | I19: 5xFAD 120 | J19: WT 181 | P19: =MID(IF(L19="","","; APP:"&L19)&IF(M19="","","; PS1:"&M19)&IF(N19="","","; AQP4:"&N19)&IF(O19="","","; CAG-EGFP:"&O19),3,200) | Q19: pending | R19: alive
A20: 5xfad-130 | B20: 5xfad | C20: 130 | E20: 46175 | F20: =IF(E20="","",ROUND((TODAY()-E20)/7,1)) -> 1.7 | G20: in_house | I20: 5xFAD 120 | J20: WT 181 | P20: =MID(IF(L20="","","; APP:"&L20)&IF(M20="","","; PS1:"&M20)&IF(N20="","","; AQP4:"&N20)&IF(O20="","","; CAG-EGFP:"&O20),3,200) | Q20: pending | R20: alive
A21: 5xfad-131 | B21: 5xfad | C21: 131 | E21: 46175 | F21: =IF(E21="","",ROUND((TODAY()-E21)/7,1)) -> 1.7 | G21: in_house | I21: 5xFAD 120 | J21: WT 181 | P21: =MID(IF(L21="","","; APP:"&L21)&IF(M21="","","; PS1:"&M21)&IF(N21="","","; AQP4:"&N21)&IF(O21="","","; CAG-EGFP:"&O21),3,200) | Q21: pending | R21: alive
A22: 5xfad-132 | B22: 5xfad | C22: 132 | E22: 46175 | F22: =IF(E22="","",ROUND((TODAY()-E22)/7,1)) -> 1.7 | G22: in_house | I22: 5xFAD 120 | J22: WT 181 | P22: =MID(IF(L22="","","; APP:"&L22)&IF(M22="","","; PS1:"&M22)&IF(N22="","","; AQP4:"&N22)&IF(O22="","","; CAG-EGFP:"&O22),3,200) | Q22: pending | R22: alive
A23: 5xfad-133 | B23: 5xfad | C23: 133 | E23: 46175 | F23: =IF(E23="","",ROUND((TODAY()-E23)/7,1)) -> 1.7 | G23: in_house | I23: 5xFAD 120 | J23: WT 181 | P23: =MID(IF(L23="","","; APP:"&L23)&IF(M23="","","; PS1:"&M23)&IF(N23="","","; AQP4:"&N23)&IF(O23="","","; CAG-EGFP:"&O23),3,200) | Q23: pending | R23: alive
A24: 5xfad-134 | B24: 5xfad | C24: 134 | E24: 46175 | F24: =IF(E24="","",ROUND((TODAY()-E24)/7,1)) -> 1.7 | G24: in_house | I24: 5xFAD 120 | J24: WT 181 | P24: =MID(IF(L24="","","; APP:"&L24)&IF(M24="","","; PS1:"&M24)&IF(N24="","","; AQP4:"&N24)&IF(O24="","","; CAG-EGFP:"&O24),3,200) | Q24: pending | R24: alive
A25: 5xfad-135 | B25: 5xfad | C25: 135 | E25: 46179 | F25: =IF(E25="","",ROUND((TODAY()-E25)/7,1)) -> 1.1 | G25: in_house | I25: 5xFAD 121 | J25: WT 182 | P25: =MID(IF(L25="","","; APP:"&L25)&IF(M25="","","; PS1:"&M25)&IF(N25="","","; AQP4:"&N25)&IF(O25="","","; CAG-EGFP:"&O25),3,200) | Q25: pending | R25: alive
A26: 5xfad-136 | B26: 5xfad | C26: 136 | E26: 46179 | F26: =IF(E26="","",ROUND((TODAY()-E26)/7,1)) -> 1.1 | G26: in_house | I26: 5xFAD 121 | J26: WT 182 | P26: =MID(IF(L26="","","; APP:"&L26)&IF(M26="","","; PS1:"&M26)&IF(N26="","","; AQP4:"&N26)&IF(O26="","","; CAG-EGFP:"&O26),3,200) | Q26: pending | R26: alive
A27: 5xfad-137 | B27: 5xfad | C27: 137 | E27: 46179 | F27: =IF(E27="","",ROUND((TODAY()-E27)/7,1)) -> 1.1 | G27: in_house | I27: 5xFAD 121 | J27: WT 182 | P27: =MID(IF(L27="","","; APP:"&L27)&IF(M27="","","; PS1:"&M27)&IF(N27="","","; AQP4:"&N27)&IF(O27="","","; CAG-EGFP:"&O27),3,200) | Q27: pending | R27: alive
A28: 5xfad-138 | B28: 5xfad | C28: 138 | E28: 46179 | F28: =IF(E28="","",ROUND((TODAY()-E28)/7,1)) -> 1.1 | G28: in_house | I28: 5xFAD 121 | J28: WT 182 | P28: =MID(IF(L28="","","; APP:"&L28)&IF(M28="","","; PS1:"&M28)&IF(N28="","","; AQP4:"&N28)&IF(O28="","","; CAG-EGFP:"&O28),3,200) | Q28: pending | R28: alive
A29: 5xfad-1 | B29: 5xfad | C29: 1 | D29: M | E29: 44991 | F29: =IF(E29="","",ROUND((TODAY()-E29)/7,1)) -> 170.9 | G29: vendor | I29: 5xFAD | J29: WT | K29: 1 | L29: +/- | M29: +/- | P29: =MID(IF(L29="","","; APP:"&L29)&IF(M29="","","; PS1:"&M29)&IF(N29="","","; AQP4:"&N29)&IF(O29="","","; CAG-EGFP:"&O29),3,200) -> APP:+/-; PS1:+/- | Q29: confirmed | R29: sacrificed | T29: Jacksonから購入（2023/6/22）
A30: 5xfad-2 | B30: 5xfad | C30: 2 | D30: M | E30: 44991 | F30: =IF(E30="","",ROUND((TODAY()-E30)/7,1)) -> 170.9 | G30: vendor | I30: 5xFAD | J30: WT | K30: 1 | L30: +/- | M30: +/- | P30: =MID(IF(L30="","","; APP:"&L30)&IF(M30="","","; PS1:"&M30)&IF(N30="","","; AQP4:"&N30)&IF(O30="","","; CAG-EGFP:"&O30),3,200) -> APP:+/-; PS1:+/- | Q30: confirmed | R30: sacrificed | T30: Jacksonから購入（2023/6/22） tag:Green tag
A31: 5xfad-3 | B31: 5xfad | C31: 3 | D31: F | E31: 44991 | F31: =IF(E31="","",ROUND((TODAY()-E31)/7,1)) -> 170.9 | G31: vendor | I31: 5xFAD | J31: WT | K31: 1 | L31: +/- | M31: +/- | P31: =MID(IF(L31="","","; APP:"&L31)&IF(M31="","","; PS1:"&M31)&IF(N31="","","; AQP4:"&N31)&IF(O31="","","; CAG-EGFP:"&O31),3,200) -> APP:+/-; PS1:+/- | Q31: confirmed | R31: sacrificed | T31: Jacksonから購入（2023/8/23） tag:Orange tag
A32: 5xfad-4 | B32: 5xfad | C32: 4 | D32: F | E32: 44991 | F32: =IF(E32="","",ROUND((TODAY()-E32)/7,1)) -> 170.9 | G32: vendor | I32: 5xFAD | J32: WT | K32: 1 | L32: +/- | M32: +/- | P32: =MID(IF(L32="","","; APP:"&L32)&IF(M32="","","; PS1:"&M32)&IF(N32="","","; AQP4:"&N32)&IF(O32="","","; CAG-EGFP:"&O32),3,200) -> APP:+/-; PS1:+/- | Q32: confirmed | R32: sacrificed | T32: Jacksonから購入（2023/8/23） tag:Orange tag
A33: 5xfad-5 | B33: 5xfad | C33: 5 | D33: M | E33: 45235 | F33: =IF(E33="","",ROUND((TODAY()-E33)/7,1)) -> 136 | G33: in_house | I33: 5xFAD-1 | J33: 5xFAD-3 | K33: 2 | L33: +/- | M33: +/- | P33: =MID(IF(L33="","","; APP:"&L33)&IF(M33="","","; PS1:"&M33)&IF(N33="","","; AQP4:"&N33)&IF(O33="","","; CAG-EGFP:"&O33),3,200) -> APP:+/-; PS1:+/- | Q33: confirmed | R33: sacrificed | T33: Suntory（プレ実験）
A34: 5xfad-6 | B34: 5xfad | C34: 6 | D34: M | E34: 45235 | F34: =IF(E34="","",ROUND((TODAY()-E34)/7,1)) -> 136 | G34: in_house | I34: 5xFAD-1 | J34: 5xFAD-3 | K34: 2 | L34: -/- | M34: -/- | P34: =MID(IF(L34="","","; APP:"&L34)&IF(M34="","","; PS1:"&M34)&IF(N34="","","; AQP4:"&N34)&IF(O34="","","; CAG-EGFP:"&O34),3,200) -> APP:-/-; PS1:-/- | Q34: confirmed | R34: sacrificed | T34: tag:左1
A35: 5xfad-7 | B35: 5xfad | C35: 7 | D35: M | E35: 45235 | F35: =IF(E35="","",ROUND((TODAY()-E35)/7,1)) -> 136 | G35: in_house | I35: 5xFAD-1 | J35: 5xFAD-3 | K35: 2 | L35: +/- | M35: +/- | P35: =MID(IF(L35="","","; APP:"&L35)&IF(M35="","","; PS1:"&M35)&IF(N35="","","; AQP4:"&N35)&IF(O35="","","; CAG-EGFP:"&O35),3,200) -> APP:+/-; PS1:+/- | Q35: confirmed | R35: sacrificed | T35: Suntory（プレ実験） tag:右1
A36: 5xfad-8 | B36: 5xfad | C36: 8 | D36: M | E36: 45235 | F36: =IF(E36="","",ROUND((TODAY()-E36)/7,1)) -> 136 | G36: in_house | I36: 5xFAD-1 | J36: 5xFAD-3 | K36: 2 | L36: +/- | M36: +/- | P36: =MID(IF(L36="","","; APP:"&L36)&IF(M36="","","; PS1:"&M36)&IF(N36="","","; AQP4:"&N36)&IF(O36="","","; CAG-EGFP:"&O36),3,200) -> APP:+/-; PS1:+/- | Q36: confirmed | R36: sacrificed | T36: Suntory（プレ実験） tag:左1右1
A37: 5xfad-9 | B37: 5xfad | C37: 9 | D37: M | E37: 45235 | F37: =IF(E37="","",ROUND((TODAY()-E37)/7,1)) -> 136 | G37: in_house | I37: 5xFAD-1 | J37: 5xFAD-3 | K37: 2 | L37: +/- | M37: +/- | P37: =MID(IF(L37="","","; APP:"&L37)&IF(M37="","","; PS1:"&M37)&IF(N37="","","; AQP4:"&N37)&IF(O37="","","; CAG-EGFP:"&O37),3,200) -> APP:+/-; PS1:+/- | Q37: confirmed | R37: sacrificed | T37: Suntory（プレ実験） tag:左2
A38: 5xfad-10 | B38: 5xfad | C38: 10 | D38: F | E38: 45235 | F38: =IF(E38="","",ROUND((TODAY()-E38)/7,1)) -> 136 | G38: in_house | I38: 5xFAD-1 | J38: 5xFAD-3 | K38: 2 | L38: +/- | M38: +/- | P38: =MID(IF(L38="","","; APP:"&L38)&IF(M38="","","; PS1:"&M38)&IF(N38="","","; AQP4:"&N38)&IF(O38="","","; CAG-EGFP:"&O38),3,200) -> APP:+/-; PS1:+/- | Q38: confirmed | R38: sacrificed
A39: 5xfad-11 | B39: 5xfad | C39: 11 | D39: F | E39: 45235 | F39: =IF(E39="","",ROUND((TODAY()-E39)/7,1)) -> 136 | G39: in_house | I39: 5xFAD-1 | J39: 5xFAD-3 | K39: 2 | L39: -/- | M39: -/- | P39: =MID(IF(L39="","","; APP:"&L39)&IF(M39="","","; PS1:"&M39)&IF(N39="","","; AQP4:"&N39)&IF(O39="","","; CAG-EGFP:"&O39),3,200) -> APP:-/-; PS1:-/- | Q39: confirmed | R39: sacrificed | T39: tag:左1
A40: 5xfad-12 | B40: 5xfad | C40: 12 | D40: M | E40: 45236 | F40: =IF(E40="","",ROUND((TODAY()-E40)/7,1)) -> 135.9 | G40: in_house | I40: 5xFAD-1 | J40: 5xFAD-4 | K40: 2 | L40: -/- | M40: -/- | P40: =MID(IF(L40="","","; APP:"&L40)&IF(M40="","","; PS1:"&M40)&IF(N40="","","; AQP4:"&N40)&IF(O40="","","; CAG-EGFP:"&O40),3,200) -> APP:-/-; PS1:-/- | Q40: confirmed | R40: sacrificed
...

Sheet projects
A1: project_id | B1: title | C1: status | D1: notes
A2: bw2025 | B2: brain water dynamics (2025_brain_water_dynamics) | C2: active | D2: 主
A3: amy2026 | B3: amyloid x glymphatic (5xFAD) | C3: active | D3: 別P

Sheet animals
A1: mouse_id | B1: birth_id | C1: cohort | D1: sex | E1: line | F1: dob_intake | G1: age_weeks | H1: sac_date | I1: fixation | J1: notes | K1: pulled_genotype
A2: ts1 | C2: personal | D2: M | E2: cagegfp | F2: 44618 | G2: =IF(F2="","",ROUND((IF(H2="",TODAY(),H2)-F2)/7,1)) -> 37.9 | H2: 44883 | I2: none | J2: s1 | K2: =IFERROR(VLOOKUP(B2,colony!$A:$T,16,FALSE()),"")
A3: ts2 | C3: personal | D3: M | E3: wt | F3: 44641 | G3: =IF(F3="","",ROUND((IF(H3="",TODAY(),H3)-F3)/7,1)) -> 34.6 | H3: 44883 | I3: other | J3: s2 | K3: =IFERROR(VLOOKUP(B3,colony!$A:$T,16,FALSE()),"")
A4: ts3 | C4: personal | D4: M | E4: wt | F4: 44781 | G4: =IF(F4="","",ROUND((IF(H4="",TODAY(),H4)-F4)/7,1)) -> 14.6 | H4: 44883 | I4: other | J4: s3 | K4: =IFERROR(VLOOKUP(B4,colony!$A:$T,16,FALSE()),"")
A5: ts4 | C5: personal | D5: M | E5: wt | F5: 44764 | G5: =IF(F5="","",ROUND((IF(H5="",TODAY(),H5)-F5)/7,1)) -> 17.4 | H5: 44886 | I5: none | J5: s4 | K5: =IFERROR(VLOOKUP(B5,colony!$A:$T,16,FALSE()),"")
A6: ts5 | C6: personal | D6: M | E6: wt | F6: 44787 | G6: =IF(F6="","",ROUND((IF(H6="",TODAY(),H6)-F6)/7,1)) -> 14.7 | H6: 44890 | I6: none | J6: s5 | K6: =IFERROR(VLOOKUP(B6,colony!$A:$T,16,FALSE()),"")
A7: ts6 | C7: personal | D7: M | E7: wt | F7: 44787 | G7: =IF(F7="","",ROUND((IF(H7="",TODAY(),H7)-F7)/7,1)) -> 14.7 | H7: 44890 | I7: none | J7: s6 | K7: =IFERROR(VLOOKUP(B7,colony!$A:$T,16,FALSE()),"")
A8: ts7 | C8: personal | D8: M | E8: cagegfp | F8: 44614 | G8: =IF(F8="","",ROUND((IF(H8="",TODAY(),H8)-F8)/7,1)) -> 39.4 | H8: 44890 | I8: none | J8: s7 | K8: =IFERROR(VLOOKUP(B8,colony!$A:$T,16,FALSE()),"")
A9: ts8 | C9: personal | D9: M | E9: cagegfp | F9: 44614 | G9: =IF(F9="","",ROUND((IF(H9="",TODAY(),H9)-F9)/7,1)) -> 39.4 | H9: 44890 | I9: none | J9: s8 | K9: =IFERROR(VLOOKUP(B9,colony!$A:$T,16,FALSE()),"")
A10: ts9 | C10: personal | D10: M | E10: wt | F10: 44785 | G10: =IF(F10="","",ROUND((IF(H10="",TODAY(),H10)-F10)/7,1)) -> 17.6 | H10: 44908 | I10: other | J10: s9 | K10: =IFERROR(VLOOKUP(B10,colony!$A:$T,16,FALSE()),"")
A11: ts10 | C11: personal | D11: M | E11: cagegfp | F11: 44767 | G11: =IF(F11="","",ROUND((IF(H11="",TODAY(),H11)-F11)/7,1)) -> 27.4 | H11: 44959 | I11: none | J11: s10 | K11: =IFERROR(VLOOKUP(B11,colony!$A:$T,16,FALSE()),"")
A12: ts11 | C12: personal | D12: F | E12: wt | F12: 45166 | G12: =IF(F12="","",ROUND((IF(H12="",TODAY(),H12)-F12)/7,1)) -> 10 | H12: 45236 | I12: none | J12: s11 | K12: =IFERROR(VLOOKUP(B12,colony!$A:$T,16,FALSE()),"")
A13: ts12 | C13: personal | D13: F | E13: wt | F13: 45166 | G13: =IF(F13="","",ROUND((IF(H13="",TODAY(),H13)-F13)/7,1)) -> 10.1 | H13: 45237 | I13: none | K13: =IFERROR(VLOOKUP(B13,colony!$A:$T,16,FALSE()),"")
A14: ts13 | C14: personal | D14: M | E14: cagegfp | F14: 44767 | G14: =IF(F14="","",ROUND((IF(H14="",TODAY(),H14)-F14)/7,1)) -> 69.4 | H14: 45253 | I14: none | K14: =IFERROR(VLOOKUP(B14,colony!$A:$T,16,FALSE()),"")
A15: ts14 | C15: personal | D15: F | E15: wt | F15: 45180 | G15: =IF(F15="","",ROUND((IF(H15="",TODAY(),H15)-F15)/7,1)) -> 9 | H15: 45243 | I15: none | K15: =IFERROR(VLOOKUP(B15,colony!$A:$T,16,FALSE()),"")
A16: ts15 | C16: personal | D16: F | E16: wt | F16: 45180 | G16: =IF(F16="","",ROUND((IF(H16="",TODAY(),H16)-F16)/7,1)) -> 9 | H16: 45243 | I16: none | K16: =IFERROR(VLOOKUP(B16,colony!$A:$T,16,FALSE()),"")
A17: ts16 | C17: personal | D17: F | E17: wt | F17: 45180 | G17: =IF(F17="","",ROUND((IF(H17="",TODAY(),H17)-F17)/7,1)) -> 9 | H17: 45243 | I17: none | K17: =IFERROR(VLOOKUP(B17,colony!$A:$T,16,FALSE()),"")
A18: ts17 | C18: personal | D18: F | E18: wt | F18: 45180 | G18: =IF(F18="","",ROUND((IF(H18="",TODAY(),H18)-F18)/7,1)) -> 9.1 | H18: 45244 | I18: none | K18: =IFERROR(VLOOKUP(B18,colony!$A:$T,16,FALSE()),"")
A19: ts18 | C19: personal | D19: F | E19: wt | F19: 45180 | G19: =IF(F19="","",ROUND((IF(H19="",TODAY(),H19)-F19)/7,1)) -> 9.1 | H19: 45244 | I19: none | K19: =IFERROR(VLOOKUP(B19,colony!$A:$T,16,FALSE()),"")
A20: ts19 | C20: personal | D20: F | E20: wt | F20: 45180 | G20: =IF(F20="","",ROUND((IF(H20="",TODAY(),H20)-F20)/7,1)) -> 9.4 | H20: 45246 | I20: none | K20: =IFERROR(VLOOKUP(B20,colony!$A:$T,16,FALSE()),"")
A21: ts20 | C21: personal | D21: F | E21: wt | F21: 45180 | G21: =IF(F21="","",ROUND((IF(H21="",TODAY(),H21)-F21)/7,1)) -> 11.1 | H21: 45258 | I21: none | K21: =IFERROR(VLOOKUP(B21,colony!$A:$T,16,FALSE()),"")
A22: ts21 | C22: personal | D22: M | E22: cagegfp | F22: 45200 | G22: =IF(F22="","",ROUND((IF(H22="",TODAY(),H22)-F22)/7,1)) -> 10.4 | H22: 45273 | I22: none | K22: =IFERROR(VLOOKUP(B22,colony!$A:$T,16,FALSE()),"")
A23: ts22 | C23: personal | D23: F | E23: wt | F23: 45180 | G23: =IF(F23="","",ROUND((IF(H23="",TODAY(),H23)-F23)/7,1)) -> 12.6 | H23: 45268 | I23: none | K23: =IFERROR(VLOOKUP(B23,colony!$A:$T,16,FALSE()),"")
A24: ts23 | C24: personal | D24: M | E24: cagegfp | F24: 45200 | G24: =IF(F24="","",ROUND((IF(H24="",TODAY(),H24)-F24)/7,1)) -> 10.7 | H24: 45275 | I24: none | K24: =IFERROR(VLOOKUP(B24,colony!$A:$T,16,FALSE()),"")
... A30: ts29 | C30: personal | D30: M | E30: cagegfp | F30: 45200 | G30: =IF(F30="","",ROUND((IF(H30="",TODAY(),H30)-F30)/7,1)) -> 15.7 | H30: 45310 | I30: none | K30: =IFERROR(VLOOKUP(B30,colony!$A:$T,16,FALSE()),"")
A31: ts30 | C31: personal | D31: M | E31: cagegfp | F31: 45240 | G31: =IF(F31="","",ROUND((IF(H31="",TODAY(),H31)-F31)/7,1)) -> 10.6 | H31: 45314 | I31: none | J31: CAG-EGFP 11 | K31: =IFERROR(VLOOKUP(B31,colony!$A:$T,16,FALSE()),"")
A32: ts31 | C32: personal | D32: M | E32: wt | F32: 45250 | G32: =IF(F32="","",ROUND((IF(H32="",TODAY(),H32)-F32)/7,1)) -> 10.1 | H32: 45321 | I32: none | K32: =IFERROR(VLOOKUP(B32,colony!$A:$T,16,FALSE()),"")
A33: ts32 | C33: personal | D33: M | E33: wt | F33: 45257 | G33: =IF(F33="","",ROUND((IF(H33="",TODAY(),H33)-F33)/7,1)) -> 10.3 | H33: 45329 | I33: none | K33: =IFERROR(VLOOKUP(B33,colony!$A:$T,16,FALSE()),"")
A34: ts33 | C34: personal | D34: M | E34: wt | F34: 45257 | G34: =IF(F34="","",ROUND((IF(H34="",TODAY(),H34)-F34)/7,1)) -> 10.3 | H34: 45329 | I34: none | K34: =IFERROR(VLOOKUP(B34,colony!$A:$T,16,FALSE()),"")
A35: ts34 | C35: personal | D35: M | E35: wt | F35: 45257 | G35: =IF(F35="","",ROUND((IF(H35="",TODAY(),H35)-F35)/7,1)) -> 10.3 | H35: 45329 | I35: none | K35: =IFERROR(VLOOKUP(B35,colony!$A:$T,16,FALSE()),"")
A36: ts35 | C36: personal | D36: M | E36: wt | F36: 45257 | G36: =IF(F36="","",ROUND((IF(H36="",TODAY(),H36)-F36)/7,1)) -> 10.3 | H36: 45329 | I36: none | K36: =IFERROR(VLOOKUP(B36,colony!$A:$T,16,FALSE()),"")
A37: ts36 | C37: personal | D37: M | E37: wt | F37: 45257 | G37: =IF(F37="","",ROUND((IF(H37="",TODAY(),H37)-F37)/7,1)) -> 10.4 | H37: 45330 | I37: none | K37: =IFERROR(VLOOKUP(B37,colony!$A:$T,16,FALSE()),"")
A38: ts37 | C38: personal | D38: M | E38: wt | F38: 45257 | G38: =IF(F38="","",ROUND((IF(H38="",TODAY(),H38)-F38)/7,1)) -> 10.4 | H38: 45330 | I38: none | K38: =IFERROR(VLOOKUP(B38,colony!$A:$T,16,FALSE()),"")
A39: ts38 | C39: personal | D39: M | E39: wt | F39: 45257 | G39: =IF(F39="","",ROUND((IF(H39="",TODAY(),H39)-F39)/7,1)) -> 10.4 | H39: 45330 | I39: none | K39: =IFERROR(VLOOKUP(B39,colony!$A:$T,16,FALSE()),"")
A40: ts39 | C40: personal | D40: M | E40: wt | F40: 45257 | G40: =IF(F40="","",ROUND((IF(H40="",TODAY(),H40)-F40)/7,1)) -> 12 | H40: 45341 | I40: none | K40: =IFERROR(VLOOKUP(B40,colony!$A:$T,16,FALSE()),"")
A41: ts40 | C41: personal | D41: M | E41: wt | F41: 45250 | G41: =IF(F41="","",ROUND((IF(H41="",TODAY(),H41)-F41)/7,1)) -> 13 | H41: 45341 | I41: none | K41: =IFERROR(VLOOKUP(B41,colony!$A:$T,16,FALSE()),"")
A42: ts41 | C42: personal | D42: M | E42: wt | F42: 45250 | G42: =IF(F42="","",ROUND((IF(H42="",TODAY(),H42)-F42)/7,1)) -> 13 | H42: 45341 | I42: none | K42: =IFERROR(VLOOKUP(B42,colony!$A:$T,16,FALSE()),"")
A43: ts42 | C43: personal | D43: M | E43: wt | F43: 45250 | G43: =IF(F43="","",ROUND((IF(H43="",TODAY(),H43)-F43)/7,1)) -> 13 | H43: 45341 | I43: none | K43: =IFERROR(VLOOKUP(B43,colony!$A:$T,16,FALSE()),"")
A44: ts43 | C44: personal | D44: M | E44: cagegfp | F44: 44991 | G44: =IF(F44="","",ROUND((IF(H44="",TODAY(),H44)-F44)/7,1)) -> 51.4 | H44: 45351 | I44: none | J44: CAG-EGFP 1 | K44: =IFERROR(VLOOKUP(B44,colony!$A:$T,16,FALSE()),"")
A45: ts44 | C45: personal | D45: M | E45: wt | F45: 45299 | G45: =IF(F45="","",ROUND((IF(H45="",TODAY(),H45)-F45)/7,1)) -> 7.4 | H45: 45351 | I45: none | K45: =IFERROR(VLOOKUP(B45,colony!$A:$T,16,FALSE()),"")
...

Sheet enrollments
A1: mouse_id | B1: project_id | C1: enroll_date | D1: role | E1: exp_status | F1: notes

Sheet procedures
A1: procedure_id | B1: mouse_id | C1: procedure_type | D1: procedure_date | E1: series_id | F1: session_no | G1: operator | H1: anesthesia | I1: analgesia | J1: construct | K1: route | L1: site1_hemi | M1: site1_region | N1: site1_ap | O1: site1_ml | P1: site1_dv | Q1: outcome | R1: notebook_scan | S1: notes
A2: pr-ts1-01 | B2: ts1 | C2: cranial_window | D2: 44720 | G2: ts | S2: チャンバーづけ
A3: pr-ts2-01 | B3: ts2 | C3: cranial_window | D3: 44721 | G3: ts | S3: チャンバーづけ
A4: pr-ts3-01 | B4: ts3 | C4: other | D4: 44876 | G4: ts | S4: FastBlue
A5: pr-ts4-01 | B5: ts4 | C5: CM_injection | D5: 44882 | G5: ts | S5: CM Catheter
A6: pr-ts4-02 | B6: ts4 | C6: cranial_window | D6: 44882 | G6: ts | S6: チャンバーづけ
A7: pr-ts5-01 | B7: ts5 | C7: CM_injection | D7: 44886 | G7: ts | S7: CM Catheter
A8: pr-ts5-02 | B8: ts5 | C8: cranial_window | D8: 44886 | G8: ts | S8: チャンバーづけ
A9: pr-ts6-01 | B9: ts6 | C9: CM_injection | D9: 44886 | G9: ts | S9: CM Catheter
A10: pr-ts6-02 | B10: ts6 | C10: cranial_window | D10: 44886 | G10: ts | S10: チャンバーづけ
A11: pr-ts7-01 | B11: ts7 | C11: CM_injection | D11: 44890 | G11: ts | S11: CM Catheter
A12: pr-ts7-02 | B12: ts7 | C12: cranial_window | D12: 44890 | G12: ts | S12: チャンバーづけ
A13: pr-ts8-01 | B13: ts8 | C13: CM_injection | D13: 44890 | G13: ts | S13: CM Catheter
... A135: pr-ts90-01 | B135: ts90 | C135: CSF_collection | D135: 45498 | G135: ts | S135: CSF Collection
A136: pr-ts91-01 | B136: ts91 | C136: viral_injection | D136: 45499 | G136: ts | J136: hsyn-EGFP | S136: AAV injection
A137: pr-ts91-02 | B137: ts91 | C137: cranial_window | D137: 45513 | G137: ts | S137: チャンバーづけ
A138: pr-ts92-01 | B138: ts92 | C138: imaging | D138: 45502 | G138: ts | S138: Fluometirc experiment
A139: pr-ts93-01 | B139: ts93 | C139: viral_injection | D139: 45504 | G139: ts | J139: hsyn-EGFP | S139: AAV injection
A140: pr-ts94-01 | B140: ts94 | C140: viral_injection | D140: 45506 | G140: ts | J140: hsyn-EGFP | S140: AAV injection
A141: pr-ts94-02 | B141: ts94 | C141: cranial_window | D141: 45541 | G141: ts | S141: チャンバーづけ
A142: pr-ts95-01 | B142: ts95 | C142: viral_injection | D142: 45509 | G142: ts | J142: hsyn-EGFP | S142: AAV injection
A143: pr-ts96-01 | B143: ts96 | C143: viral_injection | D143: 45510 | G143: ts | J143: hsyn-EGFP | S143: AAV injection
A144: pr-ts96-02 | B144: ts96 | C144: cranial_window | D144: 45548 | G144: ts | S144: チャンバーづけ
A145: pr-ts97-01 | B145: ts97 | C145: viral_injection | D145: 45510 | G145: ts | J145: hsyn-EGFP | S145: AAV injection
A146: pr-ts97-02 | B146: ts97 | C146: cranial_window | D146: 45575 | G146: ts | S146: チャンバーづけ
A147: pr-ts98-01 | B147: ts98 | C147: imaging | D147: 45524 | G147: ts | S147: Fluometirc experiment
A148: pr-ts99-01 | B148: ts99 | C148: imaging | D148: 45526 | G148: ts | S148: Fluometirc experiment
A149: pr-ts100-01 | B149: ts100 | C149: other | D149: 45540 | G149: ts | S149: water intoxication
A150: pr-ts101-01 | B150: ts101 | C150: other | D150: 45540 | G150: ts | S150: water intoxication
A151: pr-ts102-01 | B151: ts102 | C151: other | D151: 45540 | G151: ts | S151: water intoxication
A152: pr-ts103-01 | B152: ts103 | C152: other | D152: 45540 | G152: ts | S152: water intoxication
A153: pr-ts104-01 | B153: ts104 | C153: other | D153: 45540 | G153: ts | S153: water intoxication
A154: pr-ts105-01 | B154: ts105 | C154: other | D154: 45540 | G154: ts | S154: water intoxication
A155: pr-ts106-01 | B155: ts106 | C155: imaging | D155: 45545 | G155: ts | S155: Fluometric measurement
A156: pr-ts107-01 | B156: ts107 | C156: imaging | D156: 45545 | G156: ts | S156: Fluometric measurement
A157: pr-ts108-01 | B157: ts108 | C157: PoRTs_window | D157: 45545 | G157: ts | S157: PoRTs window
... A221: pr-ts164-01 | B221: ts164 | C221: tissue_clearing | D221: 45667 | G221: ts | S221: Tissue clearing
A222: pr-ts165-01 | B222: ts165 | C222: viral_injection | D222: 45671 | G222: ts | J222: hsyn-EGFP | S222: AAV injection
A223: pr-ts165-02 | B223: ts165 | C223: cranial_window | D223: 45693 | G223: ts | S223: チャンバーづけ
A224: pr-ts166-01 | B224: ts166 | C224: femoral_catheter | D224: 45672 | G224: ts | S224: Femoral vein cathter
...

Sheet matings
A1: mating_id | B1: line_id | C1: sire_id | D1: dam_id | E1: pair_start_date | F1: litter_dob | G1: litter_id | H1: n_pups | I1: n_male | J1: n_female | K1: status | L1: notes
